Workbook

Sheet Resumen
A1: CONTROL OPERATIVO ORVANN | E1: Otras referencias (Conocidas pero de nicho) | H1: Lunes | I1: Martes | J1: Miercoles | K1: Jueves | L1: Viernes | M1: Sábado | N1: Domingo
A2: Última actualización | B2: 46131 | E2: Pulp Fiction (1994)
E3: Pedro navaja | G3: 10:30 - 11:00 | H3: Kathe | I3: Kathe | J3: Kathe | K3: Kathe | L3: Kathe | M3: Andrés | O3: Kathe
A4: RESUMEN FINANCIERO | E4: Léon: The Professional | G4: 11:00 - 11.30 | H4: Kathe | I4: Kathe | J4: Kathe | K4: Kathe | L4: Kathe | M4: Andrés | O4: JP
A5: Inventario a costo: | B5: =Inventario!J2 -> 7194000 | E5: Ciudad de Dios | G5: 11.30 - 12:00 | H5: Kathe | I5: Kathe | J5: Kathe | K5: Kathe | L5: Kathe | M5: Andrés | O5: Trabajador
A6: Inventario a precio venta: | B6: =Inventario!K2 -> 14780000 | E6: Charles Bukowski (Literatura Cruda) | G6: 12:00 - 12:30 | H6: Kathe | I6: Kathe | J6: Kathe | K6: Kathe | L6: Kathe | M6: Andrés
A7: Ventas del mes: | B7: =SUMIF(Ventas!A:A,">="&DATE(YEAR(TODAY()),MONTH(TODAY()),1),Ventas!E:E) -> 3120000 | E7: Héctor Lavoe. Estilo "Vinyl Cover" | G7: 12:30 - 1:00 | H7: Kathe | I7: Kathe | J7: Kathe | K7: Kathe | L7: Kathe | M7: Andrés
A8: Gastos del mes: | B8: =SUMIF(Gastos!A:A,">="&DATE(YEAR(TODAY()),MONTH(TODAY()),1),Gastos!C:C) -> 5073445 | E8: Gabo y Cien Años de Soledad | G8: 1:00 - 1:30 | H8: Kathe | I8: Kathe | J8: Kathe | K8: Kathe | L8: Kathe | M8: Andrés
A9: Cuentas por pagar: | B9: =SUMIF('Pedidos Proveedores'!G:G,"Pendiente",'Pedidos Proveedores'!F:F) -> 0 | E9: Blade Runner (1982). | G9: 1:30 - 2:00 | H9: Kathe | I9: Kathe | J9: Kathe | K9: Kathe | L9: Andrés | M9: Andrés
A10: Utilidad bruta mes: | B10: =B7-SUMIF(Ventas!A:A,">="&DATE(YEAR(TODAY()),MONTH(TODAY()),1),Ventas!D:D)-B8 -> -3347445 | E10: Mercedes Sosa y LA FANIA. Volver a los 17 | G10: 2:00 - 2:30 | H10: Andrés | I10: Andrés | J10: Andrés | K10: Andrés | L10: Andrés | M10: Andrés
A11: Ventas Totales: | B11: =SUM(Ventas!E2:E1002) -> 11278000 | E11: Taxi Driver | G11: 2:30 - 3:00 | H11: JP | I11: JP | J11: JP | K11: Andrés | L11: Andrés | M11: Andrés
A12: Gastos Totales: | B12: =SUM(Gastos!C2:C1010) -> 39686865 | E12: Fight Club | G12: 3:00 - 3:30 | H12: JP | I12: JP | J12: JP | K12: Andrés | L12: Andrés | M12: Andrés
A13: Utilidad Bruta Total: | B13: =B11-B12 -> -28408865 | E13: Scarface | G13: 3:30 - 4:00 | H13: JP | I13: JP | J13: JP | K13: JP | L13: Andrés | M13: Andrés
E14: Vendedora de Rosas | G14: 4:00 - 4:30 | H14: JP | I14: JP | J14: JP | K14: JP | L14: Andrés | M14: Andrés
A15: ALERTAS | E15: Notorius BIG | G15: 4:30 - 5:00 | H15: JP | I15: JP | J15: JP | K15: JP | L15: Andrés | M15: Andrés
A16: Productos con stock bajo (<3): | B16: =COUNTIF(Inventario!K:K,"<3")-1 -> 87 | E16: Celia Cruz | G16: 5:00 - 5:30 | H16: JP | I16: JP | J16: JP | K16: JP | L16: Andrés | M16: Andrés
A17: Pedidos pendientes de pago: | B17: =COUNTIF('Pedidos Proveedores'!G:G,"Pendiente") -> 0 | E17: Mike Tyson | G17: 5:30 - 6:00 | H17: JP | I17: JP | J17: JP | K17: JP | L17: Andrés | M17: Andrés
E18: Principe de Bel Air | G18: 6:00 - 6:30 | H18: JP | I18: JP | J18: JP | K18: JP | L18: Andrés | M18: Andrés
E19: Jackass | G19: 6:30 - 7:00 | H19: JP | I19: JP | J19: JP | K19: JP | L19: Andrés | M19: Andrés
A20: INDICADORES CLAVE DE DESEMPEÑO | E20: Friends | G20: 7:00 - 7:30
A21: Costo promedio por prenda vendida: | B21: =IFERROR(SUMIF(Ventas!A:A,">="&DATE(YEAR(TODAY()),MONTH(TODAY()),1),Ventas!D:D)/COUNTIF(Ventas!A:A,">="&DATE(YEAR(TODAY()),MONTH(TODAY()),1)),0) -> 41000 | E21: MTV | G21: 7:30 - 8:00
A22: Ticket promedio: | B22: =IFERROR(SUMIF(Ventas!A:A,">="&DATE(YEAR(TODAY()),MONTH(TODAY()),1),Ventas!E:E)/COUNTIF(Ventas!A:A,">="&DATE(YEAR(TODAY()),MONTH(TODAY()),1)),0) -> 91764.706 | E22: Play Station 1 | G22: 8:00 - 8:30
A23: Prendas vendidas (mes): | B23: =COUNTIF(Ventas!A:A,">="&DATE(YEAR(TODAY()),MONTH(TODAY()),1)) -> 34 | E23: BackStreet Boys | G23: 8:30 - 9:00
A24: Margen bruto %: | B24: =IFERROR((SUMIF(Ventas!A:A,">="&DATE(YEAR(TODAY()),MONTH(TODAY()),1),Ventas!E:E)-SUMIF(Ventas!A:A,">="&DATE(YEAR(TODAY()),MONTH(TODAY()),1),Ventas!D:D))/SUMIF(Ventas!A:A,">="&DATE(YEAR(TODAY()),MONTH(TODAY()),1),Ventas!E:E),0) -> 0.55320513 | E24: Punk
A25: Rotación inventario: | B25: =IFERROR(COUNTIF(Ventas!A:A,">="&DATE(YEAR(TODAY()),MONTH(TODAY()),1))/Inventario!I2,0) -> 0.22222222 | C25: Mide cuántas veces se vende y se reemplaza el inventario en un período de un mes. | E25: Eminem
A26: Días de inventario: | B26: =IFERROR(Inventario!I2/(COUNTIF(Ventas!A:A,">="&DATE(YEAR(TODAY()),MONTH(TODAY()),1))/30),0) -> 135 | C26: Mide cuántos días tomaría vender el inventario actual. | E26: Tupac y BIG | G26: Kathe | H26: =COUNTIF($H$2:$N$23,G26)*0.5 -> 17
E27: Cerati y Rock Español (Soda, cadillacs,caifanes) | G27: JP | H27: =COUNTIF($H$2:$N$23,G27)*0.5 -> 17
E28: Mi pobre angelito | G28: Andrés | H28: =COUNTIF($H$2:$N$23,G28)*0.5 -> 17
A29: PUNTO DE EQUILIBRIO | E29: Manos de tijera | G29: TOTAL | H29: =SUM(H26:H28) -> 51
A30: Costos fijos mensuales: | B30: ='Costos Fijos'!B12 -> 1964900 | E30: Titanic | G30: C/U | H30: =H29/3 -> 17
A31: Margen promedio por prenda: | B31: =B24 -> 0.55320513 | E31: Sexto sentido
A32: Precio promedio venta: | B32: =B22 -> 91764.706 | E32: Marc Anthony
A33: Prendas/mes para equilibrio: | B33: =IFERROR(ROUNDUP(B30/(B32*B31),0),0) -> 39 | E33: Grupo niche
A34: Prendas/día para equilibrio: | B34: =ROUNDUP(B33/26,0) -> 2 | E34: Gran combo de las estrellas
E35: Rocky
E36: Canserbero (Raperos canon)
E37: Thalia
E38: Vicente Fernandez
E39: El principito
E40: La mascara y Show de truman (Jim Carrey)
...

Sheet Inventario
A1: INVENTARIO | I1: Total Stock: | J1: Valor Costo: | K1: Valor Venta:
I2: =SUM(K5:K1019) -> 153 | J2: =SUMPRODUCT(G5:G1019,K5:K1019) -> 7194000 | K2: =SUMPRODUCT(H5:H1019,K5:K1019) -> 14780000
J3: =SUM(J5:J313) -> 262 | K3: =SUM(K5:K313) -> 153 | L3: =SUM(L5:L313) -> 109
A4: SKU | B4: Producto | C4: Prenda | D4: Talla | E4: Color | F4: Diseño | G4: Costo | H4: Precio Venta | I4: Margen % | J4: Entradas | K4: Stock Actual | L4: Ventas | M4: Notas
A5: CAM-OVS-NEG-S | B5: Camisa Oversize Peruana S Negro | C5: Camisa Oversize Peruana | D5: S | E5: Negro | G5: 37000 | H5: 75000 | I5: =IF(H5>0,(H5-G5)/H5,0) -> 0.50666667 | J5: 2 | K5: =J5-COUNTIF(Ventas!$B$2:$B$1002,A5) -> 1 | L5: =J5-K5 -> 1
A6: CAM-OVS-NEG-M | B6: Camisa Oversize Peruana M Negro | C6: Camisa Oversize Peruana | D6: M | G6: 37000 | H6: 75000 | I6: =IF(H6>0,(H6-G6)/H6,0) -> 0.50666667 | J6: 6 | K6: =J6-COUNTIF(Ventas!$B$2:$B$1002,A6) -> 5 | L6: =J6-K6 -> 1
A7: CAM-OVS-NEG-L | B7: Camisa Oversize Peruana L Negro | C7: Camisa Oversize Peruana | D7: L | G7: 37000 | H7: 75000 | I7: =IF(H7>0,(H7-G7)/H7,0) -> 0.50666667 | J7: 6 | K7: =J7-COUNTIF(Ventas!$B$2:$B$1002,A7) -> 2 | L7: =J7-K7 -> 4
A8: CAM-OVS-NEG-XL | B8: Camisa Oversize Peruana XL Negro | C8: Camisa Oversize Peruana | D8: XL | G8: 37000 | H8: 75000 | I8: =IF(H8>0,(H8-G8)/H8,0) -> 0.50666667 | J8: 6 | K8: =J8-COUNTIF(Ventas!$B$2:$B$1002,A8) -> 4 | L8: =J8-K8 -> 2
A9: CAM-OVS-BLA-S | B9: Camisa Oversize Peruana S Blanco | C9: Camisa Oversize Peruana | G9: 37000 | H9: 75000 | I9: =IF(H9>0,(H9-G9)/H9,0) -> 0.50666667 | J9: 2 | K9: =J9-COUNTIF(Ventas!$B$2:$B$1002,A9) -> 1 | L9: =J9-K9 -> 1
A10: CAM-OVS-BLA-M | B10: Camisa Oversize Peruana M Blanco | C10: Camisa Oversize Peruana | G10: 37000 | H10: 75000 | I10: =IF(H10>0,(H10-G10)/H10,0) -> 0.50666667 | J10: 6 | K10: =J10-COUNTIF(Ventas!$B$2:$B$1002,A10) -> -2 | L10: =J10-K10 -> 8
A11: CAM-OVS-BLA-L | B11: Camisa Oversize Peruana L Blanco | C11: Camisa Oversize Peruana | G11: 37000 | H11: 75000 | I11: =IF(H11>0,(H11-G11)/H11,0) -> 0.50666667 | J11: 6 | K11: =J11-COUNTIF(Ventas!$B$2:$B$1002,A11) -> -1 | L11: =J11-K11 -> 7
A12: CAM-OVS-BLA-XL | B12: Camisa Oversize Peruana XL Blanco | C12: Camisa Oversize Peruana | G12: 37000 | H12: 75000 | I12: =IF(H12>0,(H12-G12)/H12,0) -> 0.50666667 | J12: 6 | K12: =J12-COUNTIF(Ventas!$B$2:$B$1002,A12) -> 3 | L12: =J12-K12 -> 3
A13: CAM-OVS-PER-S | B13: Camisa Oversize Peruana S Perla | C13: Camisa Oversize Peruana | G13: 37000 | H13: 75000 | I13: =IF(H13>0,(H13-G13)/H13,0) -> 0.50666667 | J13: 2 | K13: =J13-COUNTIF(Ventas!$B$2:$B$1002,A13) -> 2 | L13: =J13-K13 -> 0
A14: CAM-OVS-PER-M | B14: Camisa Oversize Peruana M Perla | C14: Camisa Oversize Peruana | G14: 37000 | H14: 75000 | I14: =IF(H14>0,(H14-G14)/H14,0) -> 0.50666667 | J14: 6 | K14: =J14-COUNTIF(Ventas!$B$2:$B$1002,A14) -> 3 | L14: =J14-K14 -> 3
A15: CAM-OVS-PER-L | B15: Camisa Oversize Peruana L Perla | C15: Camisa Oversize Peruana | G15: 37000 | H15: 75000 | I15: =IF(H15>0,(H15-G15)/H15,0) -> 0.50666667 | J15: 6 | K15: =J15-COUNTIF(Ventas!$B$2:$B$1002,A15) -> 4 | L15: =J15-K15 -> 2
A16: CAM-OVS-PER-XL | B16: Camisa Oversize Peruana XL Perla | C16: Camisa Oversize Peruana | G16: 37000 | H16: 75000 | I16: =IF(H16>0,(H16-G16)/H16,0) -> 0.50666667 | J16: 6 | K16: =J16-COUNTIF(Ventas!$B$2:$B$1002,A16) -> 3 | L16: =J16-K16 -> 3
A17: CAM-OVS-BEIG-S | B17: Camisa Oversize Peruana S Beige | C17: Camisa Oversize Peruana | G17: 37000 | H17: 75000 | I17: =IF(H17>0,(H17-G17)/H17,0) -> 0.50666667 | J17: 0 | K17: =J17-COUNTIF(Ventas!$B$2:$B$1002,A17) -> 0 | L17: =J17-K17 -> 0
A18: CAM-OVS-BEIG-M | B18: Camisa Oversize Peruana M Beige | C18: Camisa Oversize Peruana | G18: 37000 | H18: 75000 | I18: =IF(H18>0,(H18-G18)/H18,0) -> 0.50666667 | J18: 0 | K18: =J18-COUNTIF(Ventas!$B$2:$B$1002,A18) -> 0 | L18: =J18-K18 -> 0
A19: CAM-OVS-BEIG-L | B19: Camisa Oversize Peruana L Beige | C19: Camisa Oversize Peruana | G19: 37000 | H19: 75000 | I19: =IF(H19>0,(H19-G19)/H19,0) -> 0.50666667 | J19: 0 | K19: =J19-COUNTIF(Ventas!$B$2:$B$1002,A19) -> 0 | L19: =J19-K19 -> 0
A20: CAM-OVS-BEIG-XL | B20: Camisa Oversize Peruana XL Beige | C20: Camisa Oversize Peruana | G20: 37000 | H20: 75000 | I20: =IF(H20>0,(H20-G20)/H20,0) -> 0.50666667 | J20: 0 | K20: =J20-COUNTIF(Ventas!$B$2:$B$1002,A20) -> 0 | L20: =J20-K20 -> 0
... A44: HOOD-ACID-L | B44: Hoodie L Acid Wash Gris | C44: Hoodie Acid Wash | G44: 120000 | H44: 190000 | I44: =IF(H44>0,(H44-G44)/H44,0) -> 0.36842105 | J44: 12 | K44: =J44-COUNTIF(Ventas!$B$2:$B$1002,A44) -> 0 | L44: =J44-K44 -> 12
A45: CHOM-NEG-S | B45: Chompa Capucha S Negro | C45: Chompa Capucha | G45: ='Pedidos Proveedores'!$E$3 -> 90000 | H45: 180000 | I45: =IF(H45>0,(H45-G45)/H45,0) -> 0.5 | J45: 0 | K45: =J45-COUNTIF(Ventas!$B$2:$B$1002,A45) -> 0 | L45: =J45-K45 -> 0
A46: CHOM-NEG-M | B46: Chompa Capucha M Negro | C46: Chompa Capucha | G46: ='Pedidos Proveedores'!$E$3 -> 90000 | H46: 180000 | I46: =IF(H46>0,(H46-G46)/H46,0) -> 0.5 | J46: 3 | K46: =J46-COUNTIF(Ventas!$B$2:$B$1002,A46) -> 3 | L46: =J46-K46 -> 0
A47: CHOM-NEG-L | B47: Chompa Capucha L Negro | C47: Chompa Capucha | G47: ='Pedidos Proveedores'!$E$3 -> 90000 | H47: 180000 | I47: =IF(H47>0,(H47-G47)/H47,0) -> 0.5 | J47: 3 | K47: =J47-COUNTIF(Ventas!$B$2:$B$1002,A47) -> 1 | L47: =J47-K47 -> 2
A48: CHOM-PER-S | B48: Chompa Capucha S Perla | C48: Chompa Capucha | G48: ='Pedidos Proveedores'!$E$3 -> 90000 | H48: 180000 | I48: =IF(H48>0,(H48-G48)/H48,0) -> 0.5 | J48: 0 | K48: =J48-COUNTIF(Ventas!$B$2:$B$1002,A48) -> 0 | L48: =J48-K48 -> 0
A49: CHOM-PER-M | B49: Chompa Capucha M Perla | C49: Chompa Capucha | G49: ='Pedidos Proveedores'!$E$3 -> 90000 | H49: 180000 | I49: =IF(H49>0,(H49-G49)/H49,0) -> 0.5 | J49: 0 | K49: =J49-COUNTIF(Ventas!$B$2:$B$1002,A49) -> 0 | L49: =J49-K49 -> 0
A50: CHOM-PER-L | B50: Chompa Capucha L Perla | C50: Chompa Capucha | G50: ='Pedidos Proveedores'!$E$3 -> 90000 | H50: 180000 | I50: =IF(H50>0,(H50-G50)/H50,0) -> 0.5 | J50: 3 | K50: =J50-COUNTIF(Ventas!$B$2:$B$1002,A50) -> 3 | L50: =J50-K50 -> 0
A51: CHOM-VERD-S | B51: Chompa Capucha S Verde Botella | C51: Chompa Capucha | G51: ='Pedidos Proveedores'!$E$3 -> 90000 | H51: 180000 | I51: =IF(H51>0,(H51-G51)/H51,0) -> 0.5 | J51: 0 | K51: =J51-COUNTIF(Ventas!$B$2:$B$1002,A51) -> 0 | L51: =J51-K51 -> 0
A52: CHOM-VERD-M | B52: Chompa Capucha M Verde Botella | C52: Chompa Capucha | G52: ='Pedidos Proveedores'!$E$3 -> 90000 | H52: 180000 | I52: =IF(H52>0,(H52-G52)/H52,0) -> 0.5 | J52: 0 | K52: =J52-COUNTIF(Ventas!$B$2:$B$1002,A52) -> 0 | L52: =J52-K52 -> 0
A53: CHOM-VERD-L | B53: Chompa Capucha L Verde Botella | C53: Chompa Capucha | G53: ='Pedidos Proveedores'!$E$3 -> 90000 | H53: 180000 | I53: =IF(H53>0,(H53-G53)/H53,0) -> 0.5 | J53: 0 | K53: =J53-COUNTIF(Ventas!$B$2:$B$1002,A53) -> 0 | L53: =J53-K53 -> 0
A54: CHOM-PLOM-S | B54: Chompa Capucha S Plomo Plata | C54: Chompa Capucha | G54: ='Pedidos Proveedores'!$E$3 -> 90000 | H54: 180000 | I54: =IF(H54>0,(H54-G54)/H54,0) -> 0.5 | J54: 0 | K54: =J54-COUNTIF(Ventas!$B$2:$B$1002,A54) -> 0 | L54: =J54-K54 -> 0
A55: CHOM-PLOM-M | B55: Chompa Capucha M Plomo Plata | C55: Chompa Capucha | G55: ='Pedidos Proveedores'!$E$3 -> 90000 | H55: 180000 | I55: =IF(H55>0,(H55-G55)/H55,0) -> 0.5 | J55: 0 | K55: =J55-COUNTIF(Ventas!$B$2:$B$1002,A55) -> 0 | L55: =J55-K55 -> 0
A56: CHOM-PLOM-L | B56: Chompa Capucha L Plomo Plata | C56: Chompa Capucha | G56: ='Pedidos Proveedores'!$E$3 -> 90000 | H56: 180000 | I56: =IF(H56>0,(H56-G56)/H56,0) -> 0.5 | J56: 0 | K56: =J56-COUNTIF(Ventas!$B$2:$B$1002,A56) -> 0 | L56: =J56-K56 -> 0
A57: BUZ-OVS-NEG-M | B57: Buzo Cuello Redondo Oversized M Negro | C57: Buzo Cuello Redondo Oversized | G57: 55000 | H57: 120000 | I57: =IF(H57>0,(H57-G57)/H57,0) -> 0.54166667 | J57: 2 | K57: =J57-COUNTIF(Ventas!$B$2:$B$1002,A57) -> 1 | L57: =J57-K57 -> 1
A58: BUZ-OVS-NEG-L | B58: Buzo Cuello Redondo Oversized L Negro | C58: Buzo Cuello Redondo Oversized | G58: 55000 | H58: 120000 | I58: =IF(H58>0,(H58-G58)/H58,0) -> 0.54166667 | J58: 4 | K58: =J58-COUNTIF(Ventas!$B$2:$B$1002,A58) -> 2 | L58: =J58-K58 -> 2
A59: BUZ-OVS-NEG-XL | B59: Buzo Cuello Redondo Oversized XL Negro | C59: Buzo Cuello Redondo Oversized | G59: 55000 | H59: 120000 | I59: =IF(H59>0,(H59-G59)/H59,0) -> 0.54166667 | J59: 4 | K59: =J59-COUNTIF(Ventas!$B$2:$B$1002,A59) -> 2 | L59: =J59-K59 -> 2
A60: BUZ-OVS-BEIG-M | B60: Buzo Cuello Redondo Oversized M Beige | C60: Buzo Cuello Redondo Oversized | G60: 55000 | H60: 120000 | I60: =IF(H60>0,(H60-G60)/H60,0) -> 0.54166667 | J60: 2 | K60: =J60-COUNTIF(Ventas!$B$2:$B$1002,A60) -> 2 | L60: =J60-K60 -> 0
A61: BUZ-OVS-BEIG-L | B61: Buzo Cuello Redondo Oversized L Beige | C61: Buzo Cuello Redondo Oversized | G61: 55000 | H61: 120000 | I61: =IF(H61>0,(H61-G61)/H61,0) -> 0.54166667 | J61: 2 | K61: =J61-COUNTIF(Ventas!$B$2:$B$1002,A61) -> 1 | L61: =J61-K61 -> 1
A62: BUZ-OVS-BEIG-XL | B62: Buzo Cuello Redondo Oversized XL Beige | C62: Buzo Cuello Redondo Oversized | G62: 55000 | H62: 120000 | I62: =IF(H62>0,(H62-G62)/H62,0) -> 0.54166667 | J62: 2 | K62: =J62-COUNTIF(Ventas!$B$2:$B$1002,A62) -> 2 | L62: =J62-K62 -> 0
A63: BUZ-OVS-NEG-2XL | B63: Buzo Cuello Redondo Oversized 2XL Negro | C63: Buzo Cuello Redondo Oversized | G63: 55000 | H63: 120000 | I63: =IF(H63>0,(H63-G63)/H63,0) -> 0.54166667 | J63: 2 | K63: =J63-COUNTIF(Ventas!$B$2:$B$1002,A63) -> 2 | L63: =J63-K63 -> 0
...

Sheet Ventas
A1: Fecha | B1: SKU | C1: Producto | D1: Costo | E1: Precio Venta | F1: Método Pago | G1: Cliente | H1: Notas | L1: VENTAS | O1: Consignaciones (Entradas a cuenta adicionales a venta)
A2: 46067 | B2: =Inventario!A82 -> CHA-VERNEG-M | C2: =IFERROR(VLOOKUP(B2,Inventario!A:G,2,FALSE()),"") -> Chaqueta Cortavientos M Verde Botella/Negro | D2: =IFERROR(VLOOKUP(B2,Inventario!A:G,7,FALSE()),"") -> 40000 | E2: 120000 | F2: Transferencia | G2: Edison | H2: OK | K2: Efectivo | L2: =SUMIF($F$2:$F$1002,K2,$E$2:$E$1002) -> 4766000 | O2: 1000000
A3: 46067 | B3: =Inventario!A44 -> HOOD-ACID-L | C3: =IFERROR(VLOOKUP(B3,Inventario!A:G,2,FALSE()),"") -> Hoodie L Acid Wash Gris | D3: =IFERROR(VLOOKUP(B3,Inventario!A:G,7,FALSE()),"") -> 120000 | E3: =IFERROR(VLOOKUP(B3,Inventario!A:H,8,FALSE()),"") -> 190000 | F3: Efectivo | G3: Claudia Ramírez | K3: Transferencia | L3: =SUMIF($F$2:$F$1002,K3,$E$2:$E$1002) -> 5841000 | O3: 580000
A4: 46072 | B4: CHA-GRICLA-L | C4: =IFERROR(VLOOKUP(B4,Inventario!A:G,2,FALSE()),"") -> Chaqueta Cortavientos L Gris Claro | D4: =IFERROR(VLOOKUP(B4,Inventario!A:G,7,FALSE()),"") -> 40000 | E4: =IFERROR(VLOOKUP(B4,Inventario!A:H,8,FALSE()),"") -> 110000 | F4: Transferencia | G4: Sebastian Calderon | H4: OK | K4: Datáfono | L4: =SUMIF($F$2:$F$1002,K4,$E$2:$E$1002) -> 671000 | O4: 250000
A5: 46073 | B5: CAM-BOX-NEG-L | C5: =IFERROR(VLOOKUP(B5,Inventario!A:G,2,FALSE()),"") -> Camisa Boxy fit L Negro | D5: =IFERROR(VLOOKUP(B5,Inventario!A:G,7,FALSE()),"") -> 37000 | E5: =IFERROR(VLOOKUP(B5,Inventario!A:H,8,FALSE()),"") -> 75000 | F5: Efectivo | K5: Crédito | L5: =SUMIF($F$2:$F$1002,K5,$E$2:$E$1002) -> 0 | O5: 200000
A6: 46073 | B6: CAM-BOX-BLA-L | C6: =IFERROR(VLOOKUP(B6,Inventario!A:G,2,FALSE()),"") -> Camisa Boxy fit L Blanco | D6: =IFERROR(VLOOKUP(B6,Inventario!A:G,7,FALSE()),"") -> 37000 | E6: =IFERROR(VLOOKUP(B6,Inventario!A:H,8,FALSE()),"") -> 75000 | F6: Efectivo | K6: Plan separe | L6: 10000 | M6: Cliente X (10.000) - Felipe Hernandez (100.000) (M Kobe y Sudadera negra L) | O6: 100000
A7: 46077 | B7: CAM-REP-1.1 | C7: =IFERROR(VLOOKUP(B7,Inventario!A:G,2,FALSE()),"") -> Camisa Réplica 1.1 | D7: =IFERROR(VLOOKUP(B7,Inventario!A:G,7,FALSE()),"") -> 54000 | E7: 70000 | F7: Efectivo | G7: Santiago Javi | O7: =-202500*2 -> -405000
A8: 46077 | B8: CAM-REP-1.1 | C8: =IFERROR(VLOOKUP(B8,Inventario!A:G,2,FALSE()),"") -> Camisa Réplica 1.1 | D8: =IFERROR(VLOOKUP(B8,Inventario!A:G,7,FALSE()),"") -> 54000 | E8: 70000 | F8: Efectivo | G8: Santiago Javi | K8: RESUMEN VENTAS | O8: 100000 | P8: 46100
A9: 46079 | B9: CAM-REP-1.1 | C9: =IFERROR(VLOOKUP(B9,Inventario!A:G,2,FALSE()),"") -> Camisa Réplica 1.1 | D9: =IFERROR(VLOOKUP(B9,Inventario!A:G,7,FALSE()),"") -> 54000 | E9: 70000 | F9: Efectivo | K9: Total ventas: | L9: =COUNTA(B2:B502) -> 109 | O9: 500000 | P9: 46101
A10: 46080 | B10: CAM-OVS-BLA-L | C10: =IFERROR(VLOOKUP(B10,Inventario!A:G,2,FALSE()),"") -> Camisa Oversize Peruana L Blanco | D10: =IFERROR(VLOOKUP(B10,Inventario!A:G,7,FALSE()),"") -> 37000 | E10: =IFERROR(VLOOKUP(B10,Inventario!A:H,8,FALSE()),"") -> 75000 | F10: Efectivo | K10: Ingresos: | L10: =SUM(E2:E502) -> 11278000 | O10: 300000 | P10: 46107
A11: 46094 | B11: HOOD-ACID-L | C11: =IFERROR(VLOOKUP(B11,Inventario!A:G,2,FALSE()),"") -> Hoodie L Acid Wash Gris | D11: =IFERROR(VLOOKUP(B11,Inventario!A:G,7,FALSE()),"") -> 120000 | E11: =IFERROR(VLOOKUP(B11,Inventario!A:H,8,FALSE()),"") -> 190000 | F11: Transferencia | G11: Daniela Blandón | H11: OK | K11: Costo mercancía: | L11: =SUM(D2:D502) -> 5809000 | O11: 110000 | P11: 46118
A12: 46081 | B12: SUD-NEG-L | C12: =IFERROR(VLOOKUP(B12,Inventario!A:G,2,FALSE()),"") -> Sudadera Bota Recta L Negro | D12: =IFERROR(VLOOKUP(B12,Inventario!A:G,7,FALSE()),"") -> 55000 | E12: 100000 | F12: Efectivo | G12: Daniela Blandón | K12: Margen bruto: | L12: =L10-L11 -> 5469000 | O12: 10000 | P12: 46128
A13: 46083 | B13: CAM-OVS-NEG-M | C13: =IFERROR(VLOOKUP(B13,Inventario!A:G,2,FALSE()),"") -> Camisa Oversize Peruana M Negro | D13: =IFERROR(VLOOKUP(B13,Inventario!A:G,7,FALSE()),"") -> 37000 | E13: =IFERROR(VLOOKUP(B13,Inventario!A:H,8,FALSE()),"") -> 75000 | F13: Efectivo | G13: Don Darío | O13: 500000 | P13: 46130
A14: 46083 | B14: CAM-OVS-BLA-M | C14: =IFERROR(VLOOKUP(B14,Inventario!A:G,2,FALSE()),"") -> Camisa Oversize Peruana M Blanco | D14: =IFERROR(VLOOKUP(B14,Inventario!A:G,7,FALSE()),"") -> 37000 | E14: =IFERROR(VLOOKUP(B14,Inventario!A:H,8,FALSE()),"") -> 75000 | F14: Efectivo | G14: Don Darío | O14: 300000 | P14: 46140
A15: 46083 | B15: CAM-OVS-PER-M | C15: =IFERROR(VLOOKUP(B15,Inventario!A:G,2,FALSE()),"") -> Camisa Oversize Peruana M Perla | D15: =IFERROR(VLOOKUP(B15,Inventario!A:G,7,FALSE()),"") -> 37000 | E15: 80000 | F15: Efectivo | G15: Don Darío | K15: Cierre 17-3-2026 | L15: Debería | M15: Hay (6-4-2026) | N15: Hay (7-4-2026)
A16: 46084 | B16: CHA-NEG-M | C16: =IFERROR(VLOOKUP(B16,Inventario!A:G,2,FALSE()),"") -> Chaqueta Cortavientos M Negro | D16: =IFERROR(VLOOKUP(B16,Inventario!A:G,7,FALSE()),"") -> 40000 | E16: 80000 | F16: Efectivo | K16: Cuenta Ahorros | L16: =L3+O18+L4 -> 10057000 | M16: =2734000+588000-26250 -> 3295750
A17: 46085 | B17: CAM-REP-1.1 | C17: =IFERROR(VLOOKUP(B17,Inventario!A:G,2,FALSE()),"") -> Camisa Réplica 1.1 | D17: =IFERROR(VLOOKUP(B17,Inventario!A:G,7,FALSE()),"") -> 54000 | E17: =IFERROR(VLOOKUP(B17,Inventario!A:H,8,FALSE()),"") -> 75000 | F17: Transferencia | H17: OK | K17: Credito | L17: =L5 -> 0 | M17: =L17 -> 0
A18: 46085 | B18: CHA-NEG-XL | C18: =IFERROR(VLOOKUP(B18,Inventario!A:G,2,FALSE()),"") -> Chaqueta Cortavientos XL Negro | D18: =IFERROR(VLOOKUP(B18,Inventario!A:G,7,FALSE()),"") -> 40000 | E18: 100000 | F18: Transferencia | H18: OK | K18: Efectivo | L18: =L10-L16-L17-L19 -> -7499295 | M18: 229000 | O18: =SUM(O2:O17) -> 3545000
A19: 46085 | B19: CAM-OVS-BLA-L | C19: =IFERROR(VLOOKUP(B19,Inventario!A:G,2,FALSE()),"") -> Camisa Oversize Peruana L Blanco | D19: =IFERROR(VLOOKUP(B19,Inventario!A:G,7,FALSE()),"") -> 37000 | E19: =IFERROR(VLOOKUP(B19,Inventario!A:H,8,FALSE()),"") -> 75000 | F19: Efectivo | K19: Gastos | L19: =Gastos!M2 -> 8720295 | M19: =L19 -> 8720295
A20: 46085 | B20: CAM-OVS-BLA-L | C20: =IFERROR(VLOOKUP(B20,Inventario!A:G,2,FALSE()),"") -> Camisa Oversize Peruana L Blanco | D20: =IFERROR(VLOOKUP(B20,Inventario!A:G,7,FALSE()),"") -> 37000 | E20: =IFERROR(VLOOKUP(B20,Inventario!A:H,8,FALSE()),"") -> 75000 | F20: Transferencia | H20: OK | K20: =K6 -> Plan separe | L20: =L6 -> 10000 | M20: =L20 -> 10000
A21: 46085 | B21: HOOD-ACID-L | C21: =IFERROR(VLOOKUP(B21,Inventario!A:G,2,FALSE()),"") -> Hoodie L Acid Wash Gris | D21: =IFERROR(VLOOKUP(B21,Inventario!A:G,7,FALSE()),"") -> 120000 | E21: 180000 | F21: Transferencia | H21: OK | K21: Total | L21: =L19+L18+L17+L16+L20 -> 11288000 | M21: =M19+M18+M17+M16+M20 -> 12255045
A22: 46086 | B22: CAM-BOX-NEG-M | C22: =IFERROR(VLOOKUP(B22,Inventario!A:G,2,FALSE()),"") -> Camisa Boxy fit M Negro | D22: =IFERROR(VLOOKUP(B22,Inventario!A:G,7,FALSE()),"") -> 37000 | E22: 68000 | F22: Efectivo | G22: Juan Fernando | K22: Total sin separe | L22: =L16+L17+L18+L19 -> 11278000 | M22: =M16+M17+M18+M19 -> 12245045
A23: 46086 | B23: CAM-BOX-BLA-M | C23: =IFERROR(VLOOKUP(B23,Inventario!A:G,2,FALSE()),"") -> Camisa Boxy fit M Blanco | D23: =IFERROR(VLOOKUP(B23,Inventario!A:G,7,FALSE()),"") -> 37000 | E23: 68000 | F23: Efectivo | G23: Juan Fernando
A24: 46086 | B24: PANT-NEG-L | C24: =IFERROR(VLOOKUP(B24,Inventario!A:G,2,FALSE()),"") -> Pantaloneta L Negro | D24: =IFERROR(VLOOKUP(B24,Inventario!A:G,7,FALSE()),"") -> 45000 | E24: =IFERROR(VLOOKUP(B24,Inventario!A:H,8,FALSE()),"") -> 90000 | F24: Efectivo | G24: Juan Fernando | L24: DIFERENCIA | M24: =M22-L22 -> 967045
A25: 46088 | B25: CHA-GRIOSC-XL | C25: =IFERROR(VLOOKUP(B25,Inventario!A:G,2,FALSE()),"") -> Chaqueta Cortavientos XL Gris Oscuro | D25: =IFERROR(VLOOKUP(B25,Inventario!A:G,7,FALSE()),"") -> 40000 | E25: =IFERROR(VLOOKUP(B25,Inventario!A:H,8,FALSE()),"") -> 110000 | F25: Efectivo
A26: 46088 | B26: CAM-OVS-BLA-M | C26: =IFERROR(VLOOKUP(B26,Inventario!A:G,2,FALSE()),"") -> Camisa Oversize Peruana M Blanco | D26: =IFERROR(VLOOKUP(B26,Inventario!A:G,7,FALSE()),"") -> 37000 | E26: =IFERROR(VLOOKUP(B26,Inventario!A:H,8,FALSE()),"") -> 75000 | F26: Transferencia | H26: OK | K26: ROBO TARJETA
A27: 46088 | B27: CAM-REP-YOUT | C27: =IFERROR(VLOOKUP(B27,Inventario!A:G,2,FALSE()),"") -> Camisa Réplica Y/Out | D27: =IFERROR(VLOOKUP(B27,Inventario!A:G,7,FALSE()),"") -> 60000 | E27: =IFERROR(VLOOKUP(B27,Inventario!A:H,8,FALSE()),"") -> 75000 | F27: Transferencia | H27: OK
A28: 46090 | B28: CHA-NEG-XL | C28: =IFERROR(VLOOKUP(B28,Inventario!A:G,2,FALSE()),"") -> Chaqueta Cortavientos XL Negro | D28: =IFERROR(VLOOKUP(B28,Inventario!A:G,7,FALSE()),"") -> 40000 | E28: =IFERROR(VLOOKUP(B28,Inventario!A:H,8,FALSE()),"") -> 110000 | F28: Efectivo
A29: 46090 | B29: SUD-NEG-XL | C29: =IFERROR(VLOOKUP(B29,Inventario!A:G,2,FALSE()),"") -> Sudadera Bota Recta XL Negro | D29: =IFERROR(VLOOKUP(B29,Inventario!A:G,7,FALSE()),"") -> 55000 | E29: =IFERROR(VLOOKUP(B29,Inventario!A:H,8,FALSE()),"") -> 100000 | F29: Efectivo
A30: 46091 | B30: BUZ-OVS-NEG-XL | C30: =IFERROR(VLOOKUP(B30,Inventario!A:G,2,FALSE()),"") -> Buzo Cuello Redondo Oversized XL Negro | D30: =IFERROR(VLOOKUP(B30,Inventario!A:G,7,FALSE()),"") -> 55000 | E30: =IFERROR(VLOOKUP(B30,Inventario!A:H,8,FALSE()),"") -> 120000 | F30: Efectivo | G30: Colo
A31: 46091 | B31: CAM-OVS-PER-L | C31: =IFERROR(VLOOKUP(B31,Inventario!A:G,2,FALSE()),"") -> Camisa Oversize Peruana L Perla | D31: =IFERROR(VLOOKUP(B31,Inventario!A:G,7,FALSE()),"") -> 37000 | E31: 110000 | F31: Transferencia | H31: OK
A32: 46091 | B32: HOOD-ACID-L | C32: =IFERROR(VLOOKUP(B32,Inventario!A:G,2,FALSE()),"") -> Hoodie L Acid Wash Gris | D32: =IFERROR(VLOOKUP(B32,Inventario!A:G,7,FALSE()),"") -> 120000 | E32: =IFERROR(VLOOKUP(B32,Inventario!A:H,8,FALSE()),"") -> 190000 | F32: Transferencia | H32: OK
A33: 46091 | B33: SUD-NEG-L | C33: =IFERROR(VLOOKUP(B33,Inventario!A:G,2,FALSE()),"") -> Sudadera Bota Recta L Negro | D33: =IFERROR(VLOOKUP(B33,Inventario!A:G,7,FALSE()),"") -> 55000 | E33: 120000 | F33: Transferencia | H33: OK
A34: 46091 | B34: PANT-NEG-M | C34: =IFERROR(VLOOKUP(B34,Inventario!A:G,2,FALSE()),"") -> Pantaloneta M Negro | D34: =IFERROR(VLOOKUP(B34,Inventario!A:G,7,FALSE()),"") -> 45000 | E34: 85000 | F34: Transferencia | H34: OK
A35: 46091 | B35: CAM-OVS-BLA-M | C35: =IFERROR(VLOOKUP(B35,Inventario!A:G,2,FALSE()),"") -> Camisa Oversize Peruana M Blanco | D35: =IFERROR(VLOOKUP(B35,Inventario!A:G,7,FALSE()),"") -> 37000 | E35: 50000 | F35: Efectivo | G35: Carlos Ramirez
A36: 46092 | B36: CAM-REP-1.1 | C36: =IFERROR(VLOOKUP(B36,Inventario!A:G,2,FALSE()),"") -> Camisa Réplica 1.1 | D36: =IFERROR(VLOOKUP(B36,Inventario!A:G,7,FALSE()),"") -> 54000 | E36: =IFERROR(VLOOKUP(B36,Inventario!A:H,8,FALSE()),"") -> 75000 | F36: Efectivo
A37: 46092 | B37: CAM-OVS-NEG-XL | C37: =IFERROR(VLOOKUP(B37,Inventario!A:G,2,FALSE()),"") -> Camisa Oversize Peruana XL Negro | D37: =IFERROR(VLOOKUP(B37,Inventario!A:G,7,FALSE()),"") -> 37000 | E37: =IFERROR(VLOOKUP(B37,Inventario!A:H,8,FALSE()),"") -> 75000 | F37: Efectivo | G37: Dueño "Qué Bendición"
A38: 46092 | B38: CHA-VERNEG-M | C38: =IFERROR(VLOOKUP(B38,Inventario!A:G,2,FALSE()),"") -> Chaqueta Cortavientos M Verde Botella/Negro | D38: =IFERROR(VLOOKUP(B38,Inventario!A:G,7,FALSE()),"") -> 40000 | E38: 100000 | F38: Efectivo
A39: 46093 | B39: CAM-OVS-NEG-L | C39: =IFERROR(VLOOKUP(B39,Inventario!A:G,2,FALSE()),"") -> Camisa Oversize Peruana L Negro | D39: =IFERROR(VLOOKUP(B39,Inventario!A:G,7,FALSE()),"") -> 37000 | E39: 110000 | F39: Transferencia | G39: Jonathan Mazarello | H39: OK
A40: 46093 | B40: CAM-OVS-BLA-M | C40: =IFERROR(VLOOKUP(B40,Inventario!A:G,2,FALSE()),"") -> Camisa Oversize Peruana M Blanco | D40: =IFERROR(VLOOKUP(B40,Inventario!A:G,7,FALSE()),"") -> 37000 | E40: 110000 | F40: Transferencia | G40: Amparo Ramírez | H40: OK
...

Sheet Caja Diaria
A1: Fecha | B1: Efectivo Inicio | C1: Ventas Efectivo | D1: Ventas Datáfono | E1: Ventas Transf. | F1: Gastos Efectivo | G1: Efectivo Cierre | H1: Diferencia | I1: Notas
A2: 46067 | B2: 0 | C2: 0 | D2: 0 | E2: 120000 | F2: 0 | G2: =B2+C2-F2 -> 0 | H2: =G2-(B2+C2-F2) -> 0 | I2: Claudia Ramírez debe 200.000 de Hoodie Acid Wash M
G3: =B3+C3-F3 -> 0 | H3: =G3-(B3+C3-F3) -> 0
G4: =B4+C4-F4 -> 0 | H4: =G4-(B4+C4-F4) -> 0
G5: =B5+C5-F5 -> 0 | H5: =G5-(B5+C5-F5) -> 0
G6: =B6+C6-F6 -> 0 | H6: =G6-(B6+C6-F6) -> 0
G7: =B7+C7-F7 -> 0 | H7: =G7-(B7+C7-F7) -> 0
G8: =B8+C8-F8 -> 0 | H8: =G8-(B8+C8-F8) -> 0
G9: =B9+C9-F9 -> 0 | H9: =G9-(B9+C9-F9) -> 0
G10: =B10+C10-F10 -> 0 | H10: =G10-(B10+C10-F10) -> 0
G11: =B11+C11-F11 -> 0 | H11: =G11-(B11+C11-F11) -> 0
G12: =B12+C12-F12 -> 0 | H12: =G12-(B12+C12-F12) -> 0
G13: =B13+C13-F13 -> 0 | H13: =G13-(B13+C13-F13) -> 0
G14: =B14+C14-F14 -> 0 | H14: =G14-(B14+C14-F14) -> 0
... G61: =B61+C61-F61 -> 0 | H61: =G61-(B61+C61-F61) -> 0

Sheet Pedidos Proveedores
A1: Fecha Pedido | B1: Proveedor | C1: Descripción | D1: Unidades | E1: Costo Unit. | F1: Total | G1: Estado Pago | H1: Fecha Pago | I1: Notas | L1: Pendiente | M1: =SUMIF($G$2:$G$18,L1,$F$2:$F$18) -> 0 | Q1: Precios Proveedores
A2: 45692 | B2: YOUR BRAND | C2: Hoodie L | D2: 2 | E2: 120000 | F2: =D2*E2 -> 240000 | G2: Pagado | H2: 46057 | I2: 2 Acid Wash gris L | L2: Pagado | M2: =SUMIF($G$2:$G$18,L2,$F$2:$F$18) -> 13206000 | Q2: AUREN | R2: Precio
A3: 45692 | B3: YOUR BRAND | C3: Chompa 320gr Talla L | D3: 4 | E3: 90000 | F3: =D3*E3 -> 360000 | G3: Pagado | I3: 3 Perla y 1 Negro L | L3: Crédito | M3: =SUMIF($G$2:$G$18,L3,$F$2:$F$18) -> 0 | Q3: Regular | R3: 32000
A4: 46062 | B4: YOUR BRAND | C4: Hoodie L | D4: 10 | E4: 120000 | F4: =D4*E4 -> 1200000 | G4: Pagado | I4: 10 Acid Wash gris L | Q4: Oversize | R4: 35000
A5: 46062 | B5: YOUR BRAND | C5: Camiseta Boxy Fit 320gr | D5: 30 | E5: 37000 | F5: =D5*E5 -> 1110000 | G5: Pagado | I5: 10 negras, 10 blancas, 10 plomo plata | Q5: Buso regular | R5: 50000
A6: 46056 | B6: BRACOR | C6: Camiseta Réplica Y/Out 1.1 | D6: 8 | E6: 60000 | F6: =D6*E6 -> 480000 | G6: Pagado | Q6: Buso oversize | R6: 55000
A7: 46056 | B7: BRACOR | C7: Camiseta Réplica 1.1 | D7: 22 | E7: 54000 | F7: =D7*E7 -> 1188000 | G7: Pagado | Q7: Pantaloneta | R7: 45000
A8: 46067 | B8: AUREN | C8: Chaqueta Cortavientos | D8: 36 | E8: 40000 | F8: =D8*E8 -> 1440000 | G8: Pagado | I8: 24 Chaquetas 1 Color y 12 Chaquetas Bicolor | Q8: Jogger | R8: 55000
A9: 46067 | B9: AUREN | C9: Pantalonetas | D9: 12 | E9: 45000 | F9: =D9*E9 -> 540000 | G9: Pagado | I9: 12 Pantalonetas (Negras, Beige y Café) | Q9: Sudadera bota recta | R9: 55000
A10: 46067 | B10: AUREN | C10: Sudadera Bota Recta | D10: 12 | E10: 55000 | F10: =D10*E10 -> 660000 | G10: Pagado | I10: 12 Sudaderas (Negras, Beige y Café) | Q10: Chompa | R10: 75000
A11: 46067 | B11: AUREN | C11: Jogger | D11: 24 | E11: 55000 | F11: =D11*E11 -> 1320000 | G11: Pagado | I11: 12 Jogger (Negras, Beige y Café) | Q11: Chaquetas cortavientos | R11: 40000
A12: 46067 | B12: AUREN | C12: Buso Oversized | D12: 24 | E12: 55000 | F12: =D12*E12 -> 1320000 | G12: Pagado | I12: 24 Busos Oversized (Negro, Beige y Café) | Q12: Sudadera cortavientos | R12: 32000
A13: 46078 | B13: YOUR BRAND | C13: Camiseta Oversized 320gr | D13: 60 | E13: 37000 | F13: =D13*E13 -> 2220000 | G13: Pagado | I13: 20 blancas, 20 negras, 20 perla | Q13: Chaqueta reflectiva | R13: 50000
A14: 46086 | B14: YOUR BRAND | C14: Chompas 320gr | D14: 5 | E14: 90000 | F14: =D14*E14 -> 450000 | G14: Pagado | I14: 3 M y 2 L negros
A15: 46086 | B15: YOUR BRAND | C15: Camiseta Boxy Fit 220gr | D15: 2 | E15: 30000 | F15: =D15*E15 -> 60000 | G15: Pagado | I15: 2 Boxy Fit M de 220gr
A16: 46102 | B16: YOUR BRAND | C16: Camiseta Oversized 320gr | D16: 14 | E16: 37000 | F16: =D16*E16 -> 518000 | G16: Pagado | I16: 4XL Perla, 2L Perla, 4S Negra, 4L Negra
A17: 46112 | B17: AUREN | C17: Sudadera Bota Recta | D17: 1 | E17: =E10 -> 55000 | F17: =D17*E17 -> 55000 | G17: Pagado | I17: 1 Sudadera Beige S
A18: 46112 | B18: AUREN | C18: Pantaloneta | D18: 1 | E18: 45000 | F18: =D18*E18 -> 45000 | G18: Pagado | I18: 1 Pantaloneta Beige S | Q18: ETIQUETAS / MARQUILLAS / EMPAQUES
A19: 46123 | B19: YOUR BRAND | C19: Camiseta Oversized 320gr - Acid Wash | D19: 10 | E19: 36000 | F19: =D19*E19 -> 360000 | G19: Pagado | I19: 10 camisas oversize acid wash Azules
A20: 46135 | B20: YOUR BRAND | C20: Camiseta Oversized 320gr | D20: 3 | E20: 37000 | F20: =D20*E20 -> 111000 | G20: Pagado | I20: 2 negras XL y una negra S
F21: =D21*E21 -> 0
F22: =D22*E22 -> 0
A23: TOTAL PEDIDOS | D23: =SUM(D2:D22) -> 280 | F23: =SUM(F2:F18) -> 13206000 | Q23: Bolsas buenas | R23: 600
Q24: bolsa sencilla | R24: 150

Sheet Gastos
A1: Fecha | B1: Categoría | C1: Monto | D1: Descripción | E1: Método Pago | F1: Responsable | G1: Notas | I1: CATEGORÍAS DISPONIBLES: | L1: RESPONSABLES | M1: TOTAL | P1: Rubro | Q1: Fecha Periódica
A2: 45992 | B2: Arriendo | C2: 404000 | D2: Pago arriendo Diciembre | E2: Transferencia | F2: KATHE | I2: Arriendo | J2: =SUMIF(B:B,I2,C:C) -> 6058000 | L2: ORVANN | M2: =SUMIF($F$2:$F$1010,L2,$C$2:$C$1010) -> 8720295 | P2: Pago Arriendo | Q2: 1 de cada mes
A3: 45992 | B3: Arriendo | C3: 404000 | D3: Pago arriendo Diciembre | E3: Transferencia | F3: ANDRES | I3: Servicios (Agua, Luz, Gas) | J3: =SUMIF(B:B,I3,C:C) -> 563450 | L3: KATHE | M3: =SUMIF($F$2:$F$1010,L3,$C$2:$C$1010) -> 10322128 | N3: =M3-$M$7 -> -62 | P3: Pago Servicios | Q3: 22 de cada mes
A4: 45992 | B4: Arriendo | C4: 404000 | D4: Pago arriendo Diciembre | E4: Transferencia | F4: JP | I4: Internet | J4: =SUMIF(B:B,I4,C:C) -> 66000 | L4: ANDRES | M4: =SUMIF($F$2:$F$1010,L4,$C$2:$C$1010) -> 10318527 | N4: =M4-$M$7 -> -3663 | P4: Pago Internet | Q4: 14 de cada mes
A5: 45998 | B5: Dotación local | C5: 2000000 | D5: Pago arreglo Local | E5: Transferencia | F5: KATHE | I5: Nómina/Vendedor | J5: =SUMIF(B:B,I5,C:C) -> 0 | L5: JP | M5: =SUMIF($F$2:$F$1010,L5,$C$2:$C$1010) -> 10325915 | N5: =M5-$M$7 -> 3725 | P5: Pago Shopify | Q5: 30 de cada mes
A6: 45998 | B6: Dotación local | C6: 2000000 | D6: Pago arreglo Local | E6: Transferencia | F6: ANDRES | I6: Contador | J6: =SUMIF(B:B,I6,C:C) -> 0 | M6: =SUM(M3:M5) -> 30966570 | P6: Pago Correo | Q6: 1 de cada mes
A7: 45998 | B7: Dotación local | C7: 2000000 | D7: Pago arreglo Local | E7: Transferencia | F7: JP | I7: Publicidad/Marketing | J7: =SUMIF(B:B,I7,C:C) -> 2768406 | L7: Aporte por socio | M7: =M6/3 -> 10322190 | P7: Pago Seguro | Q7: 2 de cada mes
A8: 46007 | B8: Dotación local | C8: 117000 | D8: Lavamanos | E8: Transferencia | F8: JP | I8: Empaque (Bolsas, Etiquetas) | J8: =SUMIF(B:B,I8,C:C) -> 1620633
A9: 46007 | B9: Dotación local | C9: 117000 | D9: Lavamanos | E9: Transferencia | F9: ANDRES | I9: Aseo/Mantenimiento | J9: =SUMIF(B:B,I9,C:C) -> 249000
A10: 46007 | B10: Dotación local | C10: 117000 | D10: Lavamanos | E10: Transferencia | F10: KATHE | I10: Transporte | J10: =SUMIF(B:B,I10,C:C) -> 230650
A11: 46008 | B11: Dotación local | C11: 18000 | D11: Percheros pequeños | E11: Transferencia | F11: JP | I11: Comisiones datáfono | J11: =SUMIF(B:B,I11,C:C) -> 0
A12: 46008 | B12: Dotación local | C12: 18000 | D12: Percheros pequeños | E12: Transferencia | F12: ANDRES | I12: Ilustraciones/Diseño | J12: =SUMIF(B:B,I12,C:C) -> 484267
A13: 46008 | B13: Dotación local | C13: 18000 | D13: Percheros pequeños | E13: Transferencia | F13: KATHE | I13: Dotación local | J13: =SUMIF(B:B,I13,C:C) -> 10616900 | L13: DEUDAS
A14: 46018 | B14: Dotación local | C14: 500000 | D14: Pago arreglo Local | E14: Transferencia | F14: ANDRES | I14: Imprevistos | J14: =SUMIF(B:B,I14,C:C) -> 38500 | L14: Prestamista | M14: Monto | N14: Fecha de pago | O14: Notas | P14: Por Socio
A15: 46018 | B15: Dotación local | C15: 100000 | D15: Pago arreglo Local | E15: Transferencia | F15: JP | I15: Mercancía | J15: =SUMIF(B:B,I15,C:C) -> 16590724 | L15: Kathe | M15: 850500 | N15: 46149 | O15: 850.500 de excedente de celular | P15: =M15/3 -> 283500
A16: 46023 | B16: Arriendo | C16: 404000 | D16: Pago arriendo Enero | E16: Transferencia | F16: KATHE | I16: Otro | J16: =SUMIF(B:B,I16,C:C) -> 297300 | P16: =M16/3 -> 0
A17: 46023 | B17: Arriendo | C17: 404000 | D17: Pago arriendo Enero | E17: Transferencia | F17: JP | I17: Seguros | J17: =SUMIF(B:B,I17,C:C) -> 103035 | P17: =M17/3 -> 0
A18: 46023 | B18: Arriendo | C18: 404000 | D18: Pago arriendo Enero | E18: Transferencia | F18: ANDRES | P18: =M18/3 -> 0
A19: 46024 | B19: Publicidad/Marketing | C19: 59682 | D19: Pago mensualidad Freepick y Mockey | E19: Transferencia | F19: JP | I19: RESUMEN GASTOS | P19: =M19/3 -> 0
A20: 46024 | B20: Publicidad/Marketing | C20: 59682 | D20: Pago mensualidad Freepick y Mockey | E20: Transferencia | F20: KATHE | I20: Total gastos: | J20: =SUM(C2:C510) -> 39686865
A21: 46024 | B21: Publicidad/Marketing | C21: 59682 | D21: Pago mensualidad Freepick y Mockey | E21: Transferencia | F21: ANDRES | L21: TOTAL DEUDAS | M21: =SUM(M15:M19) -> 850500
A22: 46032 | B22: Dotación local | C22: 287000 | D22: Espejo, Toldo y Cámaras | E22: Transferencia | F22: JP | L22: Por socio | M22: =M21/3 -> 283500
A23: 46032 | B23: Dotación local | C23: 287000 | D23: Espejo, Toldo y Cámaras | E23: Transferencia | F23: KATHE
A24: 46032 | B24: Dotación local | C24: 287000 | D24: Espejo, Toldo y Cámaras | E24: Transferencia | F24: ANDRES
A25: 46037 | B25: Dotación local | C25: 30000 | D25: Adicional espejo | E25: Transferencia | F25: ANDRES | L25: Otras deudas
A26: 46037 | B26: Dotación local | C26: 30000 | D26: Adicional espejo | E26: Transferencia | F26: JP | L26: Pendiente | M26: Monto | N26: Fecha de pago | O26: Notas
A27: 46037 | B27: Dotación local | C27: 30000 | D27: Adicional espejo | E27: Transferencia | F27: KATHE
A28: 45674 | B28: Dotación local | C28: 220000 | D28: Pago arreglo Local | E28: Transferencia | F28: ANDRES
A29: 45674 | B29: Dotación local | C29: 720000 | D29: Pago arreglo Local | E29: Transferencia | F29: KATHE
A30: 45674 | B30: Dotación local | C30: 60000 | D30: Pago arreglo Local | E30: Transferencia | F30: JP
A31: 46043 | B31: Dotación local | C31: 6700 | D31: Nombre Carpa | E31: Transferencia | F31: ANDRES | L31: TOTAL | M31: =SUM(M27:M30) -> 0
A32: 46043 | B32: Dotación local | C32: 6700 | D32: Nombre Carpa | E32: Transferencia | F32: KATHE | L32: C/U | M32: =M31/3 -> 0
A33: 46043 | B33: Dotación local | C33: 6700 | D33: Nombre Carpa | E33: Transferencia | F33: JP
A34: 46052 | B34: Ilustraciones/Diseño | C34: 140000 | D34: Diseño Colección 1 (Pulp Fiction) | E34: Transferencia | F34: JP
A35: 46052 | B35: Ilustraciones/Diseño | C35: 140000 | D35: Diseño Colección 1 (Pulp Fiction) | E35: Transferencia | F35: KATHE
A36: 46052 | B36: Ilustraciones/Diseño | C36: 140000 | D36: Diseño Colección 1 (Pulp Fiction) | E36: Transferencia | F36: ANDRES
A37: 46056 | B37: Arriendo | C37: 404000 | D37: Pago Arriendo Febrero | E37: Transferencia | F37: JP
A38: 46056 | B38: Arriendo | C38: 404000 | D38: Pago Arriendo Febrero | E38: Transferencia | F38: KATHE
A39: 46056 | B39: Arriendo | C39: 404000 | D39: Pago Arriendo Febrero | E39: Transferencia | F39: ANDRES
A40: 46059 | B40: Dotación local | C40: 400000 | D40: Pago arreglo Local | E40: Transferencia | F40: JP
...

Sheet Costos Fijos
A1: COSTOS FIJOS MENSUALES
A3: CONCEPTO | B3: MONTO (COP) | C3: NOTAS
A4: Arriendo mensual | B4: 1210000
A5: Servicios públicos | B5: 220000 | C5: Estimado
A6: Internet | B6: 69000 | C6: Primeros dos meses $34.500
A7: Persona punto de venta | C7: Por ahora atienden socios (Una vez haya persona vale 3.000.000 mensual)
A8: Digitales | B8: =100000+53000+60000 -> 213000 | C8: Shopify, Google Workspace (Dominio), Capcut
A9: Seguros | B9: 103000
A10: Imprevistos | B10: =SUM(B4:B6)*0.1 -> 149900 | C10: 10% del total
A12: TOTAL | B12: =SUM(B4:B10) -> 1964900

Sheet Análisis Precios
A1: ANÁLISIS DE COSTO REAL POR TIPO DE PRENDA
A2: Incluye: Prenda + Estampado + Etiquetas + Empaque
A4: COSTOS ADICIONALES (EDITAR EN AZUL) | F4: Siempre precio llevando los diseños listos
A5: Concepto | B5: 1-10 uds | C5: 11-50 uds | D5: 51-100 uds | E5: Más de 100 | F5: Notas
A6: Estampado DTF pequeño (pecho) | B6: =25000/8 -> 3125 | C6: =25000/10 -> 2500 | D6: =25000/10 -> 2500 | E6: =25000/12 -> 2083.3333 | F6: Se vende por metro. El metro vale aproximadamente 25.000. Salen tamaño (Aprox 57 cm de ancho): punto corazon (Logo pequeño), media carta (Logo estandar tipo clemont), carta (Figura tamaño carta), oficio y tabloide (Casi estampado completo). Salen unos 100 punto corazón, unas 15 media carta, unas 8 carta, unas 6 oficio y 2 tabloides.
A7: Estampado DTF grande (espalda) | B7: =25000/2 -> 12500 | C7: =25000/3 -> 8333.3333 | D7: =25000/3 -> 8333.3333 | E7: =25000/4 -> 6250 | F7: Llenar después de cotizar
A8: Estampado Serigrafía (1 color) | B8: $8,000 | C8: $5,000 | D8: $3,500 | E8: $2,500 | F8: El metro de vinilo de alta densidad vale aprox 105.000 (sumando el estampado (72.000) plotteado y descolillado (33.000), si se averigua seguro es más barato) - Solo negro, blanco y rojo normalmente / El metro de vinilo vale aprox 80.000 (sumando el estampado (45.000) plotteado y descolillado (35.000), si se averigua seguro es más barato) - Solo negro, blanco y rojo normalmente. Vinilo sale en un solo color, DTF varios. Vinilo queda con un poco de relieve. DTG no se encontró (Proveedor Santiago)
A9: Etiqueta cuello tejida | B9: 1500 | C9: 1000 | D9: 800 | E9: 600 | F9: Mínimo típico: 100 uds
A10: Hang tag (etiqueta colgante) | B10: 1200 | C10: $800 | D10: $600 | E10: $400 | F10: Con diseño e hilo
A11: Bolsa papel con logo | B11: 1500 | C11: 1000 | D11: 800 | E11: 800
A12: Bolsa premium | B12: 3000 | C12: 3000 | D12: 2500 | E12: 2000 | F12: Bolsa Premium
A13: Sticker logo | B13: 500 | C13: 300 | D13: 200 | E13: 150 | F13: Para sellar bolsa y dejar adentro
A16: COSTO REAL POR TIPO DE PRODUCTO
A17: Tipo Prenda | B17: Costo Base AUREN | C17: Estampado | D17: Etiquetas | E17: Empaque | F17: COSTO TOTAL | G17: Precio Venta Sugerido | H17: Margen %
A18: Camisa Básica (sin estampar) | B18: 37000 | C18: 0 | D18: =$B$9+$B$10 -> 2700 | E18: =$B$11+$B$12+$B$13 -> 5000 | F18: =SUM(B18:E18) -> 44700 | G18: 80000 | H18: =IF(G18>0,(G18-F18)/G18,0) -> 0.44125
A19: Camisa Estampada Pecho | B19: 37000 | C19: =B6 -> 3125 | D19: =$B$9+$B$10 -> 2700 | E19: =$B$11+$B$12+$B$13 -> 5000 | F19: =SUM(B19:E19) -> 47825 | G19: 80000 | H19: =IF(G19>0,(G19-F19)/G19,0) -> 0.4021875
A20: Camisa Estampada Espalda | B20: 37000 | C20: =B7 -> 12500 | D20: =$B$9+$B$10 -> 2700 | E20: =$B$11+$B$12+$B$13 -> 5000 | F20: =SUM(B20:E20) -> 57200 | G20: 80000 | H20: =IF(G20>0,(G20-F20)/G20,0) -> 0.285
A21: Camisa Estampada Full (pecho+espalda) | B21: 37000 | C21: =C19+C20 -> 15625 | D21: =$B$9+$B$10 -> 2700 | E21: =$B$11+$B$12+$B$13 -> 5000 | F21: =SUM(B21:E21) -> 60325 | G21: 80000 | H21: =IF(G21>0,(G21-F21)/G21,0) -> 0.2459375
A22: Chompa Capucha Básica | B22: 76000 | C22: $0 | D22: =$B$9+$B$10 -> 2700 | E22: =$B$11+$B$12+$B$13 -> 5000 | F22: =SUM(B22:E22) -> 83700 | G22: 120000 | H22: =IF(G22>0,(G22-F22)/G22,0) -> 0.3025
A23: Chompa Capucha Estampada | B23: 76000 | C23: =C21 -> 15625 | D23: =$B$9+$B$10 -> 2700 | E23: =$B$11+$B$12+$B$13 -> 5000 | F23: =SUM(B23:E23) -> 99325 | G23: 130000 | H23: =IF(G23>0,(G23-F23)/G23,0) -> 0.23596154
A24: Buzo Cuello Redondo Básico | B24: 56000 | C24: $0 | D24: =$B$9+$B$10 -> 2700 | E24: =$B$11+$B$12+$B$13 -> 5000 | F24: =SUM(B24:E24) -> 63700 | G24: 100000 | H24: =IF(G24>0,(G24-F24)/G24,0) -> 0.363
A25: Buzo Estampado | B25: 56000 | C25: =C23 -> 15625 | D25: =$B$9+$B$10 -> 2700 | E25: =$B$11+$B$12+$B$13 -> 5000 | F25: =SUM(B25:E25) -> 79325 | G25: 120000 | H25: =IF(G25>0,(G25-F25)/G25,0) -> 0.33895833
A26: Jogger Básico | B26: 62000 | C26: $0 | D26: =$B$9+$B$10 -> 2700 | E26: =$B$11+$B$12+$B$13 -> 5000 | F26: =SUM(B26:E26) -> 69700 | G26: 100000 | H26: =IF(G26>0,(G26-F26)/G26,0) -> 0.303
A27: Sudadera Bota Recta Básica | B27: 62000 | C27: $0 | D27: =$B$9+$B$10 -> 2700 | E27: =$B$11+$B$12+$B$13 -> 5000 | F27: =SUM(B27:E27) -> 69700 | G27: 100000 | H27: =IF(G27>0,(G27-F27)/G27,0) -> 0.303
A28: Pantaloneta Básica | B28: 49000 | C28: $0 | D28: =$B$9+$B$10 -> 2700 | E28: =$B$11+$B$12+$B$13 -> 5000 | F28: =SUM(B28:E28) -> 56700 | G28: 80000 | H28: =IF(G28>0,(G28-F28)/G28,0) -> 0.29125
A29: Chaqueta Cortavientos Básica | B29: 45000 | C29: $0 | D29: =$B$9+$B$10 -> 2700 | E29: =$B$11+$B$12+$B$13 -> 5000 | F29: =SUM(B29:E29) -> 52700 | G29: 80000 | H29: =IF(G29>0,(G29-F29)/G29,0) -> 0.34125
A30: Chaqueta Cortavientos Estampada | B30: 45000 | C30: =C25 -> 15625 | D30: =$B$9+$B$10 -> 2700 | E30: =$B$11+$B$12+$B$13 -> 5000 | F30: =SUM(B30:E30) -> 68325 | G30: 100000 | H30: =IF(G30>0,(G30-F30)/G30,0) -> 0.31675
A34: ESCENARIOS DE PRECIO DE VENTA - CAMISA ESTAMPADA
A35: Escenario | B35: Costo Total | C35: Precio Venta | D35: Margen $ | E35: Margen % | F35: Comentario
A36: Económico (réplica) | B36: =F21 -> 60325 | C36: 80000 | D36: =C36-B36 -> 19675 | E36: =IF(C36>0,(C36-B36)/C36,0) -> 0.2459375 | F36: Competir con réplicas baratas
A37: Estándar | B37: =F21 -> 60325 | C37: 90000 | D37: =C37-B37 -> 29675 | E37: =IF(C37>0,(C37-B37)/C37,0) -> 0.32972222 | F37: Precio medio del mercado
A38: Premium ORVANN | B38: =F21 -> 60325 | C38: 110000 | D38: =C38-B38 -> 49675 | E38: =IF(C38>0,(C38-B38)/C38,0) -> 0.45159091 | F38: Marca propia, diseño exclusivo
A39: Ultra Premium (edición limitada) | B39: =F21*1.1 -> 66357.5 | C39: 140000 | D39: =C39-B39 -> 73642.5 | E39: =IF(C39>0,(C39-B39)/C39,0) -> 0.52601786 | F39: Colección especial, empaque VHS/Vinilo
A42: NOTAS IMPORTANTES:
A43: Los precios en AZUL son inputs
A44: Para réplicas (Clemont, etc): menor margen pero mayor volumen
A45: Para colecciones ORVANN: mayor margen, menor volumen, más exclusividad

Sheet P.Eq  Proyeccion
A1: MODELO FINANCIERO — ORVANN
A2: Punto de Equilibrio y Proyección de Flujo de Caja a 6 Meses
A4: 1. SUPUESTOS DEL MODELO
A5: Fuente de datos: | B5: Calculado de 38 ventas reales registradas
A7: Costos fijos mensuales | B7: ='Costos Fijos'!B12 -> 1964900
A8: Precio promedio de venta por prenda | B8: =Resumen!B22 -> 91764.706
A9: Costo promedio por prenda | B9: =Resumen!B21 -> 41000
A10: Margen bruto promedio por prenda | B10: =B8-B9 -> 50764.706
A11: Margen bruto % | B11: =B10/B8 -> 0.55320513
A13: 2. PUNTO DE EQUILIBRIO
A14: Fórmula: Costos Fijos / Margen por prenda
A16: Prendas a vender por MES para cubrir costos | B16: =ROUNDUP(B7/B10,0) -> 39
A17: Prendas a vender por DÍA (26 días/mes) | B17: =ROUNDUP(B16/26,0) -> 2
A18: Ventas mensuales mínimas para equilibrio | B18: =B16*B8 -> 3578823.5
A20: 3. PROYECCIÓN FLUJO DE CAJA — 6 MESES (Escenario Base)
A21: Escenario de ventas (prendas/día) | B21: =B17+1 -> 3 | C21: ← Cambiar para simular
B23: Mes 1 | C23: Mes 2 | D23: Mes 3 | E23: Mes 4 | F23: Mes 5 | G23: Mes 6 | H23: TOTAL
A24: Días operativos | B24: 26 | C24: 26 | D24: 26 | E24: 26 | F24: 26 | G24: 26 | H24: =SUM(B24:G24) -> 156
A25: Prendas vendidas | B25: =$B$21*B24 -> 78 | C25: =$B$21*C24 -> 78 | D25: =$B$21*D24 -> 78 | E25: =$B$21*E24 -> 78 | F25: =$B$21*F24 -> 78 | G25: =$B$21*G24 -> 78 | H25: =SUM(B25:G25) -> 468
A27: INGRESOS
A28: Ventas brutas | B28: =B25*$B$8 -> 7157647.1 | C28: =C25*$B$8 -> 7157647.1 | D28: =D25*$B$8 -> 7157647.1 | E28: =E25*$B$8 -> 7157647.1 | F28: =F25*$B$8 -> 7157647.1 | G28: =G25*$B$8 -> 7157647.1 | H28: =SUM(B28:G28) -> 42945882
A30: EGRESOS
A31: Costo mercancía | B31: =B25*$B$9 -> 3198000 | C31: =C25*$B$9 -> 3198000 | D31: =D25*$B$9 -> 3198000 | E31: =E25*$B$9 -> 3198000 | F31: =F25*$B$9 -> 3198000 | G31: =G25*$B$9 -> 3198000 | H31: =SUM(B31:G31) -> 19188000
A32: Estampaciones y empaques (8%) | B32: =B31*8% -> 255840 | C32: =C31*8% -> 255840 | D32: =D31*8% -> 255840 | E32: =E31*8% -> 255840 | F32: =F31*8% -> 255840 | G32: =G31*8% -> 255840 | H32: =SUM(B32:G32) -> 1535040
A33: Costos fijos | B33: =$B$7 -> 1964900 | C33: =$B$7 -> 1964900 | D33: =$B$7 -> 1964900 | E33: =$B$7 -> 1964900 | F33: =$B$7 -> 1964900 | G33: =$B$7 -> 1964900 | H33: =SUM(B33:G33) -> 11789400
A34: Total egresos | B34: =B31+B32+B33 -> 5418740 | C34: =C31+C32+C33 -> 5418740 | D34: =D31+D32+D33 -> 5418740 | E34: =E31+E32+E33 -> 5418740 | F34: =F31+F32+F33 -> 5418740 | G34: =G31+G32+G33 -> 5418740 | H34: =H31+H32+H33 -> 32512440
A36: RESULTADO
A37: Utilidad mensual | B37: =B28-B34 -> 1738907.1 | C37: =C28-C34 -> 1738907.1 | D37: =D28-D34 -> 1738907.1 | E37: =E28-E34 -> 1738907.1 | F37: =F28-F34 -> 1738907.1 | G37: =G28-G34 -> 1738907.1 | H37: =SUM(B37:G37) -> 10433442
A38: Utilidad por socio (3) | B38: =B37/3 -> 579635.69 | C38: =C37/3 -> 579635.69 | D38: =D37/3 -> 579635.69 | E38: =E37/3 -> 579635.69 | F38: =F37/3 -> 579635.69 | G38: =G37/3 -> 579635.69 | H38: =H37/3 -> 3477814.1
A39: Margen neto % | B39: =IFERROR(B37/B28,0) -> 0.24294395 | C39: =IFERROR(C37/C28,0) -> 0.24294395 | D39: =IFERROR(D37/D28,0) -> 0.24294395 | E39: =IFERROR(E37/E28,0) -> 0.24294395 | F39: =IFERROR(F37/F28,0) -> 0.24294395 | G39: =IFERROR(G37/G28,0) -> 0.24294395 | H39: =IFERROR(H37/H28,0) -> 0.24294395
A41: 4. COMPARACIÓN DE ESCENARIOS (Mensual)
B43: Conservador | C43: Base | D43: Optimista | E43: Con Empleado
A44: Prendas/día | B44: 2 | C44: =B21 -> 3 | D44: 5 | E44: 6
A45: Prendas/mes (26 días) | B45: =B44*26 -> 52 | C45: =C44*26 -> 78 | D45: =D44*26 -> 130 | E45: =E44*26 -> 156
A47: Ingresos mensuales | B47: =B45*$B$8 -> 4771764.7 | C47: =C45*$B$8 -> 7157647.1 | D47: =D45*$B$8 -> 11929412 | E47: =E45*$B$8 -> 14315294
A48: Costo mercancía + estampado | B48: =B45*$B$9*1.08 -> 2302560 | C48: =C45*$B$9*1.08 -> 3453840 | D48: =D45*$B$9*1.08 -> 5756400 | E48: =E45*$B$9*1.08 -> 6907680
A49: Costos fijos | B49: =$B$7 -> 1964900 | C49: =$B$7 -> 1964900 | D49: =$B$7 -> 1964900 | E49: =$B$7+3000000 -> 4964900
A50: Total egresos | B50: =B48+B49 -> 4267460 | C50: =C48+C49 -> 5418740 | D50: =D48+D49 -> 7721300 | E50: =E48+E49 -> 11872580
A52: UTILIDAD MENSUAL | B52: =B47-B50 -> 504304.71 | C52: =C47-C50 -> 1738907.1 | D52: =D47-D50 -> 4208111.8 | E52: =E47-E50 -> 2442714.1
A53: UTILIDAD POR SOCIO | B53: =B52/3 -> 168101.57 | C53: =C52/3 -> 579635.69 | D53: =D52/3 -> 1402703.9 | E53: =E52/3 -> 814238.04
...

Sheet Cotizador
A1: COTIZADOR DE COMPRAS - ORVANN | C1: Estampado grande DTG | D1: Estampado Punto Corazón DTG | E1: Punto Corazón bordado | F1: Etiquetas Espalda | G1: Marquillas lavado | H1: Bolsa
C2: 12000 | D2: 2000 | E2: 7000 | F2: 600 | G2: 600 | H2: 1000
A3: CATÁLOGO DE PRODUCTOS (Referencia de Costos)
A4: Tipo Producto | B4: Proveedor | C4: Costo Base | D4: Estampado Punto Corazón | E4: Bordado Punto Corazón | F4: Estampado Completo | G4: Etiquetas | H4: Empaque | I4: Costo Unitario | J4: Precio Venta Unitario | K4: Ganancia | L4: Margen | M4: Precio unitario x3 | N4: Precio x3 | O4: Ganancia x3 | P4: Margen x3 | Q4: Precio unitario x6 | R4: Precio x6 | S4: Ganancia x6 | T4: Margen x6 | U4: Precio Unit x12 | V4: Precio x12 | W4: Ganancia x12 | X4: Margen x12 | Y4: Precio Unit x60 + | Z4: Precio x60 + | AA4: Ganancia x60 + | AB4: Margen x60 +
A5: Camisa Oversize | B5: AUREN | C5: 35000 | G5: =$F$2+$G$2 -> 1200 | H5: =$H$2 -> 1000 | I5: =SUM(C5:H5) -> 37200 | J5: 75000 | K5: =J5-I5 -> 37800 | L5: =IF(J5>0,(J5-$I5)/J5,0) -> 0.504 | M5: =ROUNDUP($J5*0.9,-3) -> 68000 | N5: =M5*3 -> 204000 | O5: =N5-I5*3 -> 92400 | P5: =IF(N5>0,(N5-$I5*3)/N5,0) -> 0.45294118 | Q5: =ROUNDUP($J5*0.85,-3) -> 64000 | R5: =Q5*6 -> 384000 | S5: =R5-I5*6 -> 160800 | T5: =IF(R5>0,(R5-$I5*6)/R5,0) -> 0.41875 | U5: =ROUNDUP($J5*0.8,-3) -> 60000 | V5: =U5*12 -> 720000 | W5: =V5-I5*12 -> 273600 | X5: =IF(V5>0,(V5-$I5*12)/V5,0) -> 0.38 | Y5: =ROUNDUP($J5*0.7,-3) -> 53000 | Z5: =Y5*60 -> 3180000 | AA5: =Z5-I5*60 -> 948000 | AB5: =IF(Z5>0,(Z5-$I5*60)/Z5,0) -> 0.29811321
A6: Camisa Oversize Peruana Estampada Punto Corazón | B6: YOUR BRAND | C6: 37000 | D6: =$D$2 -> 2000 | G6: =$F$2+$G$2 -> 1200 | H6: =$H$2 -> 1000 | I6: =SUM(C6:H6) -> 41200 | J6: 120000 | K6: =J6-I6 -> 78800 | L6: =IF(J6>0,(J6-$I6)/J6,0) -> 0.65666667 | M6: =ROUNDUP($J6*0.9,-3) -> 108000 | N6: =M6*3 -> 324000 | O6: =N6-I6*3 -> 200400 | P6: =IF(N6>0,(N6-$I6*3)/N6,0) -> 0.61851852 | Q6: =ROUNDUP($J6*0.85,-3) -> 102000 | R6: =Q6*6 -> 612000 | S6: =R6-I6*6 -> 364800 | T6: =IF(R6>0,(R6-$I6*6)/R6,0) -> 0.59607843 | U6: =ROUNDUP($J6*0.8,-3) -> 96000 | V6: =U6*12 -> 1152000 | W6: =V6-I6*12 -> 657600 | X6: =IF(V6>0,(V6-$I6*12)/V6,0) -> 0.57083333 | Y6: =ROUNDUP($J6*0.7,-3) -> 84000 | Z6: =Y6*60 -> 5040000 | AA6: =Z6-I6*60 -> 2568000 | AB6: =IF(Z6>0,(Z6-$I6*60)/Z6,0) -> 0.50952381
A7: Camisa Oversize Peruana Bordada Punto Corazón | B7: YOUR BRAND | C7: 37000 | E7: =$E$2 -> 7000 | G7: =$F$2+$G$2 -> 1200 | H7: =$H$2 -> 1000 | I7: =SUM(C7:H7) -> 46200 | J7: 120000 | K7: =J7-I7 -> 73800 | L7: =IF(J7>0,(J7-$I7)/J7,0) -> 0.615 | M7: =ROUNDUP($J7*0.9,-3) -> 108000 | N7: =M7*3 -> 324000 | O7: =N7-I7*3 -> 185400 | P7: =IF(N7>0,(N7-$I7*3)/N7,0) -> 0.57222222 | Q7: =ROUNDUP($J7*0.85,-3) -> 102000 | R7: =Q7*6 -> 612000 | S7: =R7-I7*6 -> 334800 | T7: =IF(R7>0,(R7-$I7*6)/R7,0) -> 0.54705882 | U7: =ROUNDUP($J7*0.8,-3) -> 96000 | V7: =U7*12 -> 1152000 | W7: =V7-I7*12 -> 597600 | X7: =IF(V7>0,(V7-$I7*12)/V7,0) -> 0.51875 | Y7: =ROUNDUP($J7*0.7,-3) -> 84000 | Z7: =Y7*60 -> 5040000 | AA7: =Z7-I7*60 -> 2268000 | AB7: =IF(Z7>0,(Z7-$I7*60)/Z7,0) -> 0.45
A8: Camisa Oversize Peruana Bordado Punto Corazón + Estampado Completo | B8: YOUR BRAND | C8: 37000 | E8: =$E$2 -> 7000 | F8: =$C$2 -> 12000 | G8: =$F$2+$G$2 -> 1200 | H8: =$H$2 -> 1000 | I8: =SUM(C8:H8) -> 58200 | J8: 120000 | K8: =J8-I8 -> 61800 | L8: =IF(J8>0,(J8-$I8)/J8,0) -> 0.515 | M8: =ROUNDUP($J8*0.9,-3) -> 108000 | N8: =M8*3 -> 324000 | O8: =N8-I8*3 -> 149400 | P8: =IF(N8>0,(N8-$I8*3)/N8,0) -> 0.46111111 | Q8: =ROUNDUP($J8*0.85,-3) -> 102000 | R8: =Q8*6 -> 612000 | S8: =R8-I8*6 -> 262800 | T8: =IF(R8>0,(R8-$I8*6)/R8,0) -> 0.42941176 | U8: =ROUNDUP($J8*0.8,-3) -> 96000 | V8: =U8*12 -> 1152000 | W8: =V8-I8*12 -> 453600 | X8: =IF(V8>0,(V8-$I8*12)/V8,0) -> 0.39375 | Y8: =ROUNDUP($J8*0.7,-3) -> 84000 | Z8: =Y8*60 -> 5040000 | AA8: =Z8-I8*60 -> 1548000 | AB8: =IF(Z8>0,(Z8-$I8*60)/Z8,0) -> 0.30714286
A9: Camisa Oversize Peruana Estampado Punto Corazón + Estampado Completo | B9: YOUR BRAND | C9: 37000 | D9: =$D$2 -> 2000 | F9: =$C$2 -> 12000 | G9: =$F$2+$G$2 -> 1200 | H9: =$H$2 -> 1000 | I9: =SUM(C9:H9) -> 53200 | J9: 120000 | K9: =J9-I9 -> 66800 | L9: =IF(J9>0,(J9-$I9)/J9,0) -> 0.55666667 | M9: =ROUNDUP($J9*0.9,-3) -> 108000 | N9: =M9*3 -> 324000 | O9: =N9-I9*3 -> 164400 | P9: =IF(N9>0,(N9-$I9*3)/N9,0) -> 0.50740741 | Q9: =ROUNDUP($J9*0.85,-3) -> 102000 | R9: =Q9*6 -> 612000 | S9: =R9-I9*6 -> 292800 | T9: =IF(R9>0,(R9-$I9*6)/R9,0) -> 0.47843137 | U9: =ROUNDUP($J9*0.8,-3) -> 96000 | V9: =U9*12 -> 1152000 | W9: =V9-I9*12 -> 513600 | X9: =IF(V9>0,(V9-$I9*12)/V9,0) -> 0.44583333 | Y9: =ROUNDUP($J9*0.7,-3) -> 84000 | Z9: =Y9*60 -> 5040000 | AA9: =Z9-I9*60 -> 1848000 | AB9: =IF(Z9>0,(Z9-$I9*60)/Z9,0) -> 0.36666667
A10: Camisa Oversize Peruana Básica | B10: YOUR BRAND | C10: 37000 | G10: =$F$2+$G$2 -> 1200 | H10: =$H$2 -> 1000 | I10: =SUM(C10:H10) -> 39200 | J10: 75000 | K10: =J10-I10 -> 35800 | L10: =IF(J10>0,(J10-$I10)/J10,0) -> 0.47733333 | M10: =ROUNDUP($J10*0.9,-3) -> 68000 | N10: =M10*3 -> 204000 | O10: =N10-I10*3 -> 86400 | P10: =IF(N10>0,(N10-$I10*3)/N10,0) -> 0.42352941 | Q10: =ROUNDUP($J10*0.85,-3) -> 64000 | R10: =Q10*6 -> 384000 | S10: =R10-I10*6 -> 148800 | T10: =IF(R10>0,(R10-$I10*6)/R10,0) -> 0.3875 | U10: =ROUNDUP($J10*0.8,-3) -> 60000 | V10: =U10*12 -> 720000 | W10: =V10-I10*12 -> 249600 | X10: =IF(V10>0,(V10-$I10*12)/V10,0) -> 0.34666667 | Y10: =ROUNDUP($J10*0.7,-3) -> 53000 | Z10: =Y10*60 -> 3180000 | AA10: =Z10-I10*60 -> 828000 | AB10: =IF(Z10>0,(Z10-$I10*60)/Z10,0) -> 0.26037736
A11: Camisa Regular Peruana Estampada Punto Corazón | B11: YOUR BRAND | C11: 37000 | D11: =$D$2 -> 2000 | G11: =$F$2+$G$2 -> 1200 | H11: =$H$2 -> 1000 | I11: =SUM(C11:H11) -> 41200 | J11: 120000 | K11: =J11-I11 -> 78800 | L11: =IF(J11>0,(J11-$I11)/J11,0) -> 0.65666667 | M11: =ROUNDUP($J11*0.9,-3) -> 108000 | N11: =M11*3 -> 324000 | O11: =N11-I11*3 -> 200400 | P11: =IF(N11>0,(N11-$I11*3)/N11,0) -> 0.61851852 | Q11: =ROUNDUP($J11*0.85,-3) -> 102000 | R11: =Q11*6 -> 612000 | S11: =R11-I11*6 -> 364800 | T11: =IF(R11>0,(R11-$I11*6)/R11,0) -> 0.59607843 | U11: =ROUNDUP($J11*0.8,-3) -> 96000 | V11: =U11*12 -> 1152000 | W11: =V11-I11*12 -> 657600 | X11: =IF(V11>0,(V11-$I11*12)/V11,0) -> 0.57083333 | Y11: =ROUNDUP($J11*0.7,-3) -> 84000 | Z11: =Y11*60 -> 5040000 | AA11: =Z11-I11*60 -> 2568000 | AB11: =IF(Z11>0,(Z11-$I11*60)/Z11,0) -> 0.50952381
A12: Camisa Regular Peruana Bordada Punto Corazón | B12: YOUR BRAND | C12: 37000 | E12: =$E$2 -> 7000 | G12: =$F$2+$G$2 -> 1200 | H12: =$H$2 -> 1000 | I12: =SUM(C12:H12) -> 46200 | J12: 120000 | K12: =J12-I12 -> 73800 | L12: =IF(J12>0,(J12-$I12)/J12,0) -> 0.615 | M12: =ROUNDUP($J12*0.9,-3) -> 108000 | N12: =M12*3 -> 324000 | O12: =N12-I12*3 -> 185400 | P12: =IF(N12>0,(N12-$I12*3)/N12,0) -> 0.57222222 | Q12: =ROUNDUP($J12*0.85,-3) -> 102000 | R12: =Q12*6 -> 612000 | S12: =R12-I12*6 -> 334800 | T12: =IF(R12>0,(R12-$I12*6)/R12,0) -> 0.54705882 | U12: =ROUNDUP($J12*0.8,-3) -> 96000 | V12: =U12*12 -> 1152000 | W12: =V12-I12*12 -> 597600 | X12: =IF(V12>0,(V12-$I12*12)/V12,0) -> 0.51875 | Y12: =ROUNDUP($J12*0.7,-3) -> 84000 | Z12: =Y12*60 -> 5040000 | AA12: =Z12-I12*60 -> 2268000 | AB12: =IF(Z12>0,(Z12-$I12*60)/Z12,0) -> 0.45
A13: Camisa Regular Peruana Bordado Punto Corazón + Estampado Completo | B13: YOUR BRAND | C13: 37000 | E13: =$E$2 -> 7000 | F13: =$C$2 -> 12000 | G13: =$F$2+$G$2 -> 1200 | H13: =$H$2 -> 1000 | I13: =SUM(C13:H13) -> 58200 | J13: 120000 | K13: =J13-I13 -> 61800 | L13: =IF(J13>0,(J13-$I13)/J13,0) -> 0.515 | M13: =ROUNDUP($J13*0.9,-3) -> 108000 | N13: =M13*3 -> 324000 | O13: =N13-I13*3 -> 149400 | P13: =IF(N13>0,(N13-$I13*3)/N13,0) -> 0.46111111 | Q13: =ROUNDUP($J13*0.85,-3) -> 102000 | R13: =Q13*6 -> 612000 | S13: =R13-I13*6 -> 262800 | T13: =IF(R13>0,(R13-$I13*6)/R13,0) -> 0.42941176 | U13: =ROUNDUP($J13*0.8,-3) -> 96000 | V13: =U13*12 -> 1152000 | W13: =V13-I13*12 -> 453600 | X13: =IF(V13>0,(V13-$I13*12)/V13,0) -> 0.39375 | Y13: =ROUNDUP($J13*0.7,-3) -> 84000 | Z13: =Y13*60 -> 5040000 | AA13: =Z13-I13*60 -> 1548000 | AB13: =IF(Z13>0,(Z13-$I13*60)/Z13,0) -> 0.30714286
A14: Camisa Regular Peruana Estampado Punto Corazón + Estampado Completo | B14: YOUR BRAND | C14: 37000 | D14: =$D$2 -> 2000 | F14: =$C$2 -> 12000 | G14: =$F$2+$G$2 -> 1200 | H14: =$H$2 -> 1000 | I14: =SUM(C14:H14) -> 53200 | J14: 120000 | K14: =J14-I14 -> 66800 | L14: =IF(J14>0,(J14-$I14)/J14,0) -> 0.55666667 | M14: =ROUNDUP($J14*0.9,-3) -> 108000 | N14: =M14*3 -> 324000 | O14: =N14-I14*3 -> 164400 | P14: =IF(N14>0,(N14-$I14*3)/N14,0) -> 0.50740741 | Q14: =ROUNDUP($J14*0.85,-3) -> 102000 | R14: =Q14*6 -> 612000 | S14: =R14-I14*6 -> 292800 | T14: =IF(R14>0,(R14-$I14*6)/R14,0) -> 0.47843137 | U14: =ROUNDUP($J14*0.8,-3) -> 96000 | V14: =U14*12 -> 1152000 | W14: =V14-I14*12 -> 513600 | X14: =IF(V14>0,(V14-$I14*12)/V14,0) -> 0.44583333 | Y14: =ROUNDUP($J14*0.7,-3) -> 84000 | Z14: =Y14*60 -> 5040000 | AA14: =Z14-I14*60 -> 1848000 | AB14: =IF(Z14>0,(Z14-$I14*60)/Z14,0) -> 0.36666667
A15: Camisa Regular Peruana Básica | B15: YOUR BRAND | C15: 37000 | G15: =$F$2+$G$2 -> 1200 | H15: =$H$2 -> 1000 | I15: =SUM(C15:H15) -> 39200 | J15: 75000 | K15: =J15-I15 -> 35800 | L15: =IF(J15>0,(J15-$I15)/J15,0) -> 0.47733333 | M15: =ROUNDUP($J15*0.9,-3) -> 68000 | N15: =M15*3 -> 204000 | O15: =N15-I15*3 -> 86400 | P15: =IF(N15>0,(N15-$I15*3)/N15,0) -> 0.42352941 | Q15: =ROUNDUP($J15*0.85,-3) -> 64000 | R15: =Q15*6 -> 384000 | S15: =R15-I15*6 -> 148800 | T15: =IF(R15>0,(R15-$I15*6)/R15,0) -> 0.3875 | U15: =ROUNDUP($J15*0.8,-3) -> 60000 | V15: =U15*12 -> 720000 | W15: =V15-I15*12 -> 249600 | X15: =IF(V15>0,(V15-$I15*12)/V15,0) -> 0.34666667 | Y15: =ROUNDUP($J15*0.7,-3) -> 53000 | Z15: =Y15*60 -> 3180000 | AA15: =Z15-I15*60 -> 828000 | AB15: =IF(Z15>0,(Z15-$I15*60)/Z15,0) -> 0.26037736
A16: Camisa Boxy fit Peruana Estampada Punto Corazón | B16: YOUR BRAND | C16: 37000 | D16: =$D$2 -> 2000 | G16: =$F$2+$G$2 -> 1200 | H16: =$H$2 -> 1000 | I16: =SUM(C16:H16) -> 41200 | J16: 120000 | K16: =J16-I16 -> 78800 | L16: =IF(J16>0,(J16-$I16)/J16,0) -> 0.65666667 | M16: =ROUNDUP($J16*0.9,-3) -> 108000 | N16: =M16*3 -> 324000 | O16: =N16-I16*3 -> 200400 | P16: =IF(N16>0,(N16-$I16*3)/N16,0) -> 0.61851852 | Q16: =ROUNDUP($J16*0.85,-3) -> 102000 | R16: =Q16*6 -> 612000 | S16: =R16-I16*6 -> 364800 | T16: =IF(R16>0,(R16-$I16*6)/R16,0) -> 0.59607843 | U16: =ROUNDUP($J16*0.8,-3) -> 96000 | V16: =U16*12 -> 1152000 | W16: =V16-I16*12 -> 657600 | X16: =IF(V16>0,(V16-$I16*12)/V16,0) -> 0.57083333 | Y16: =ROUNDUP($J16*0.7,-3) -> 84000 | Z16: =Y16*60 -> 5040000 | AA16: =Z16-I16*60 -> 2568000 | AB16: =IF(Z16>0,(Z16-$I16*60)/Z16,0) -> 0.50952381
